<?xml version="1.0" ?>
<robot xmlns:xacro="http://ros.org/wiki/xacro">
<xacro:macro name="coaliron_16ton" params="prefix">

    <!-- link list -->
    <link name="${prefix}link_0">
        <visual>
            <origin xyz="0 0 0" rpy="0 0 0"/>
            <geometry>
                <box size="0.1 0.3 0.1" />
            </geometry>
        </visual>
        <collision>
            <origin xyz="0 0 0" rpy="0 0 0"/>
            <geometry>
                <box size="0.1 0.3 0.1" />
            </geometry>
        </collision>
    </link>
    <link name="${prefix}link_1">
        <visual>
            <origin xyz="0 0 0" rpy="0 0 0"/>
            <geometry>
                <box size="0.1 0.3 0.1" />
            </geometry>
        </visual>
        <collision>
            <origin xyz="0 0 0" rpy="0 0 0"/>
            <geometry>
                <box size="0.1 0.3 0.1" />
            </geometry>
        </collision>
    </link>
    <!-- end of link list -->

    <!-- joint list -->
    <joint name="${prefix}joint_1" type="prismatic">
        <parent link="${prefix}link_0"/>
        <child link="${prefix}link_1"/>
        <origin xyz="0 0 0" rpy="0 0 0" />
        <axis xyz="0 0 -1" />
        <limit lower="0" upper="0.1524" effort="100" velocity="10"/>
    </joint>
    <!-- end of joint list -->

    </xacro:macro>
</robot>

